<robot name="test_robot">
    <link name="world" />
    <link name="base_cylinder">
        <visual>
            <geometry>
                <mesh filename="package://dexter/src/meshes/base_cylinder.stl" scale="0.001 0.001 0.001" />
            </geometry>
        </visual>
        <collision>
            <geometry>
                <mesh filename="package://dexter/src/meshes/base_cylinder.stl" scale="0.001 0.001 0.001" />
            </geometry>
        </collision>
        
<inertial>
            <mass value="0.1" />
            <inertia ixx="0.03" iyy="0.03" izz="0.03" ixy="0.0" ixz="0.0" iyz="0.0" />
        </inertial>

    </link>
    <link name="platform">
        <visual>
            <geometry>
                <mesh filename="package://dexter/src/meshes/top_plate.stl" />
            </geometry>
        </visual>
        <collision>
            <geometry>
                <mesh filename="package://dexter/src/meshes/top_plate.stl" />
            </geometry>
        </collision>
        
<inertial>
            <mass value="0.1" />
            <inertia ixx="0.03" iyy="0.03" izz="0.03" ixy="0.0" ixz="0.0" iyz="0.0" />
        </inertial>

    </link>
    <link name="lower_arm">
        <visual>
            <geometry>
                <mesh filename="package://dexter/src/meshes/lower_arm.stl" />
            </geometry>
        </visual>
        <collision>
            <geometry>
                <mesh filename="package://dexter/src/meshes/lower_arm.stl" />
            </geometry>
        </collision>
        
<inertial>
            <mass value="0.1" />
            <inertia ixx="0.03" iyy="0.03" izz="0.03" ixy="0.0" ixz="0.0" iyz="0.0" />
        </inertial>

    </link>
    <link name="upper_arm">
        <visual>
            <geometry>
                <mesh filename="package://dexter/src/meshes/top_arm.stl" />
            </geometry>
        </visual>
        <collision>
            <geometry>
                <mesh filename="package://dexter/src/meshes/top_arm.stl" />
            </geometry>
        </collision>
        
<inertial>
            <mass value="0.1" />
            <inertia ixx="0.03" iyy="0.03" izz="0.03" ixy="0.0" ixz="0.0" iyz="0.0" />
        </inertial>

    </link>
    <link name="wrist">
        <visual>
            <geometry>
                <mesh filename="package://dexter/src/meshes/wrist.stl" />
            </geometry>
        </visual>
        <collision>
            <geometry>
                <mesh filename="package://dexter/src/meshes/wrist.stl" />
            </geometry>
        </collision>
        
<inertial>
            <mass value="0.1" />
            <inertia ixx="0.03" iyy="0.03" izz="0.03" ixy="0.0" ixz="0.0" iyz="0.0" />
        </inertial>

    </link>
    <link name="claw_base">
        <visual>
            <geometry>
                <mesh filename="package://dexter/src/meshes/clawbase.stl" />
            </geometry>
        </visual>
        <collision>
            <geometry>
                <mesh filename="package://dexter/src/meshes/clawbase.stl" />
            </geometry>
        </collision>
        
<inertial>
            <mass value="0.1" />
            <inertia ixx="0.03" iyy="0.03" izz="0.03" ixy="0.0" ixz="0.0" iyz="0.0" />
        </inertial>

    </link>
    <link name="claw_l">
        <visual>
            <geometry>
                <mesh filename="package://dexter/src/meshes/clawl.stl" />
            </geometry>
        </visual>
        <collision>
            <geometry>
                <mesh filename="package://dexter/src/meshes/clawl.stl" />
            </geometry>
        </collision>
        
<inertial>
            <mass value="0.1" />
            <inertia ixx="0.03" iyy="0.03" izz="0.03" ixy="0.0" ixz="0.0" iyz="0.0" />
        </inertial>

    </link>
    <link name="claw_r">
        <visual>
            <geometry>
                <mesh filename="package://dexter/src/meshes/clawr.stl" />
            </geometry>
        </visual>
        <collision>
            <geometry>
                <mesh filename="package://dexter/src/meshes/clawr.stl" />
            </geometry>
        </collision>
        
<inertial>
            <mass value="0.1" />
            <inertia ixx="0.03" iyy="0.03" izz="0.03" ixy="0.0" ixz="0.0" iyz="0.0" />
        </inertial>

    </link>
    <joint name="fixed" type="fixed">
        <parent link="world" />
        <child link="base_cylinder" />
    </joint>
    <joint name="joint1" type="revolute">
        <axis xyz="0 0 1" />
        <limit effort="1000.0" lower="-1.708" upper="1.708" velocity="1.0" />
        <parent link="base_cylinder" />
        <child link="platform" />
    </joint>
    <joint name="joint2" type="revolute">
        <axis xyz="-1 0 0" />
        <limit effort="1000.0" lower="-1.708" upper="1.708" velocity="1.0" />
        <origin xyz="0 0 0.093" rpy="0 0 0" />
        <parent link="platform" />
        <child link="lower_arm" />
    </joint>
    <joint name="joint3" type="revolute">
        <axis xyz="1 0 0" />
        <limit effort="1000.0" lower="-1.708" upper="1.708" velocity="1.0" />
        <origin xyz="0 0 0.121" rpy="0 0 0" />
        <parent link="lower_arm" />
        <child link="upper_arm" />
    </joint>
    <joint name="joint4" type="revolute">
        <axis xyz="-1 0 0" />
        <limit effort="1000.0" lower="-1.708" upper="1.708" velocity="1.0" />
        <origin xyz="0 0 0.112" rpy="0 0 0" />
        <parent link="upper_arm" />
        <child link="wrist" />
    </joint>
    <joint name="joint5" type="fixed">
        <axis xyz="-1 0 0" />
        <origin xyz="0 0 0.112" rpy="0 0 0" />
        <parent link="wrist" />
        <child link="claw_base" />
    </joint>
    <joint name="joint6" type="revolute">
        <axis xyz="0 1 0" />
        <limit effort="1000.0" lower="-0.15" upper="0.30" velocity="1.0" />
        <origin xyz="-0.027 0 0" rpy="0 0 0" />
        <parent link="claw_base" />
        <child link="claw_l" />
    </joint>
    <joint name="joint7" type="revolute">
        <axis xyz="0 -1 0" />
        <limit effort="1000.0" lower="-0.15" upper="0.30" velocity="1.0" />
        <origin xyz="-0.027 0 0" rpy="0 0 0" />
        <parent link="claw_base" />
        <child link="claw_r" />
    </joint>
    
<transmission name="trans_joint1">
        <type>PositionJointInterface</type>
        <joint name="joint1">
            <hardwareInterface>PositionJointInterface</hardwareInterface>
        </joint>
        <actuator name="joint1_motor">
            <hardwareInterface>PositionJointInterface</hardwareInterface>
            <mechanicalReduction>1</mechanicalReduction>
        </actuator>
    </transmission>
    <transmission name="trans_joint2">
        <type>PositionJointInterface</type>
        <joint name="joint2">
            <hardwareInterface>PositionJointInterface</hardwareInterface>
        </joint>
        <actuator name="joint2_motor">
            <hardwareInterface>PositionJointInterface</hardwareInterface>
            <mechanicalReduction>1</mechanicalReduction>
        </actuator>
    </transmission>
    <transmission name="trans_joint3">
        <type>PositionJointInterface</type>
        <joint name="joint3">
            <hardwareInterface>PositionJointInterface</hardwareInterface>
        </joint>
        <actuator name="joint3_motor">
            <hardwareInterface>PositionJointInterface</hardwareInterface>
            <mechanicalReduction>1</mechanicalReduction>
        </actuator>
    </transmission>
    <transmission name="trans_joint4">
        <type>PositionJointInterface</type>
        <joint name="joint4">
            <hardwareInterface>PositionJointInterface</hardwareInterface>
        </joint>
        <actuator name="joint4_motor">
            <hardwareInterface>PositionJointInterface</hardwareInterface>
            <mechanicalReduction>1</mechanicalReduction>
        </actuator>
    </transmission>
    <transmission name="trans_joint6">
        <type>PositionJointInterface</type>
        <joint name="joint6">
            <hardwareInterface>PositionJointInterface</hardwareInterface>
        </joint>
        <actuator name="joint6_motor">
            <hardwareInterface>PositionJointInterface</hardwareInterface>
            <mechanicalReduction>1</mechanicalReduction>
        </actuator>
    </transmission>
    <transmission name="trans_joint7">
        <type>PositionJointInterface</type>
        <joint name="joint7">
            <hardwareInterface>PositionJointInterface</hardwareInterface>
        </joint>
        <actuator name="joint7_motor">
            <hardwareInterface>PositionJointInterface</hardwareInterface>
            <mechanicalReduction>1</mechanicalReduction>
        </actuator>
    </transmission>
    <gazebo>
        <plugin name="gazebo_ros_control" filename="libgazebo_ros_control.so">
            <robotNamespace>/</robotNamespace>
        </plugin>
    </gazebo>
    <gazebo>
        <plugin name="joint_state_publisher"
                filename="libgazebo_ros_joint_state_publisher.so">
            
            <jointName>joint1,joint2,joint3,joint4,joint6,joint7</jointName>
            </plugin>
    </gazebo>
</robot>
